<?xml version="1.0" ?>
<!-- =================================================================================== -->
<!-- |    This document was autogenerated by xacro from probot_anno.xacro              | -->
<!-- |    EDITING THIS FILE BY HAND IS NOT RECOMMENDED                                 | -->
<!-- =================================================================================== -->
<robot name="probot_anno">
  <link name="base_footprint"/>
  <joint name="joint_0" type="fixed">
    <origin rpy="0 0 0" xyz="0 0 0.0532"/>
    <parent link="base_footprint"/>
    <child link="base_link"/>
  </joint>
  <link name="base_link">
    <inertial>
      <origin rpy="0 0 0" xyz="-0.010934 0.23134 0.0051509"/>
      <mass value="0.286755864167795"/>
      <inertia ixx="0.000914891478336648" ixy="-9.74616219194614E-08" ixz="-1.22707969258407E-10" iyy="0.000918304334803416" iyz="-7.53317610970858E-09" izz="0.00181941891671005"/>
    </inertial>
    <visual>
      <origin rpy="0 0 0" xyz="0.017266 0 0"/>
      <geometry>
        <mesh filename="package://probot_description/meshes/base_link.STL"/>
      </geometry>
      <material name="robot_color">
        <color rgba="0.79216 0.81961 0.93333 1"/>
      </material>
    </visual>
    <collision>
      <origin rpy="0 0 0" xyz="0.017266 0 0"/>
      <geometry>
        <mesh filename="package://probot_description/meshes/base_link.STL"/>
      </geometry>
    </collision>
  </link>
  <link name="link_1">
    <inertial>
      <origin rpy="0 0 0" xyz="-0.010934 0.23134 0.0051509"/>
      <mass value="1.50473234946919"/>
      <inertia ixx="0.00667121219534555" ixy="-8.54445620252032E-06" ixz="1.56560865622562E-07" iyy="0.00595997019373921" iyz="0.000424090863023404" izz="0.006430374759868"/>
    </inertial>
    <visual>
      <origin rpy="0 0 0" xyz="0 0 0"/>
      <geometry>
        <mesh filename="package://probot_description/meshes/link_1.STL"/>
      </geometry>
      <material name="robot_color">
        <color rgba="0.79216 0.81961 0.93333 1"/>
      </material>
    </visual>
    <collision>
      <origin rpy="0 0 0" xyz="0 0 0"/>
      <geometry>
        <mesh filename="package://probot_description/meshes/link_1.STL"/>
      </geometry>
    </collision>
  </link>
  <joint name="joint_1" type="revolute">
    <origin rpy="1.5708 0 0" xyz="0 0 0"/>
    <parent link="base_link"/>
    <child link="link_1"/>
    <axis xyz="0 1 0"/>
    <limit effort="100" lower="-3.1416" upper="3.1416" velocity="3"/>
  </joint>
  <link name="link_2">
    <inertial>
      <origin rpy="0 0 0" xyz="-0.010934 0.23134 0.0051509"/>
      <mass value="1.00050619907027"/>
      <inertia ixx="0.0014522332353461" ixy="-8.9482731163037E-06" ixz="2.82386498605548E-05" iyy="0.00136522040691973" iyz="3.07414967244519E-06" izz="0.0024851244648194"/>
    </inertial>
    <visual>
      <origin rpy="0 0 0" xyz="0 0 0"/>
      <geometry>
        <mesh filename="package://probot_description/meshes/link_2.STL"/>
      </geometry>
      <material name="robot_color">
        <color rgba="0.79216 0.81961 0.93333 1"/>
      </material>
    </visual>
    <collision>
      <origin rpy="0 0 0" xyz="0 0 0"/>
      <geometry>
        <mesh filename="package://probot_description/meshes/link_2.STL"/>
      </geometry>
    </collision>
  </link>
  <joint name="joint_2" type="revolute">
    <origin rpy="0 0 0" xyz="0 0.2305 0"/>
    <parent link="link_1"/>
    <child link="link_2"/>
    <axis xyz="0 0 1"/>
    <limit effort="100" lower="-2.0071" upper="2.0071" velocity="3"/>
  </joint>
  <link name="link_3">
    <inertial>
      <origin rpy="0 0 0" xyz="-0.010934 0.23134 0.0051509"/>
      <mass value="0.549520755006072"/>
      <inertia ixx="0.000672536702276881" ixy="-6.59360128441997E-06" ixz="-9.19434642556495E-07" iyy="0.000480817179261754" iyz="4.15241325610066E-06" izz="0.001032595781869"/>
    </inertial>
    <visual>
      <origin rpy="0 0 0" xyz="0 0 0"/>
      <geometry>
        <mesh filename="package://probot_description/meshes/link_3.STL"/>
      </geometry>
      <material name="robot_color">
        <color rgba="0.79216 0.81961 0.93333 1"/>
      </material>
    </visual>
    <collision>
      <origin rpy="0 0 0" xyz="0 0 0"/>
      <geometry>
        <mesh filename="package://probot_description/meshes/link_3.STL"/>
      </geometry>
    </collision>
  </link>
  <joint name="joint_3" type="revolute">
    <origin rpy="0 0 0" xyz="0 0.225 0"/>
    <parent link="link_2"/>
    <child link="link_3"/>
    <axis xyz="0 0 1"/>
    <limit effort="100" lower="-0.6981" upper="3.8397" velocity="3"/>
  </joint>
  <link name="link_4">
    <inertial>
      <origin rpy="0 0 0" xyz="-0.010934 0.23134 0.0051509"/>
      <mass value="0.952497713016407"/>
      <inertia ixx="0.00530614361480367" ixy="7.10404845280282E-20" ixz="-3.14301719378985E-20" iyy="0.00354259274696511" iyz="-6.5480532041068E-19" izz="0.00221010202882688"/>
    </inertial>
    <visual>
      <origin rpy="0 0 0" xyz="0 0 0"/>
      <geometry>
        <mesh filename="package://probot_description/meshes/link_4.STL"/>
      </geometry>
      <material name="robot_color">
        <color rgba="0.79216 0.81961 0.93333 1"/>
      </material>
    </visual>
    <collision>
      <origin rpy="0 0 0" xyz="0 0 0"/>
      <geometry>
        <mesh filename="package://probot_description/meshes/link_4.STL"/>
      </geometry>
    </collision>
  </link>
  <joint name="joint_4" type="revolute">
    <origin rpy="0 0 0" xyz="0.021 0 0.002"/>
    <parent link="link_3"/>
    <child link="link_4"/>
    <axis xyz="1 0 0"/>
    <limit effort="100" lower="-3.1416" upper="3.1416" velocity="3"/>
  </joint>
  <link name="link_5">
    <inertial>
      <origin rpy="0 0 0" xyz="-0.010934 0.23134 0.0051509"/>
      <mass value="0.393287799668792"/>
      <inertia ixx="0.000319382332386347" ixy="-9.00754957688623E-10" ixz="-1.75182555785641E-09" iyy="0.000272873273899642" iyz="-4.5738506474632E-10" izz="0.000292993325719614"/>
    </inertial>
    <visual>
      <origin rpy="0 0 0" xyz="0 0 0"/>
      <geometry>
        <mesh filename="package://probot_description/meshes/link_5.STL"/>
      </geometry>
      <material name="robot_color">
        <color rgba="0.79216 0.81961 0.93333 1"/>
      </material>
    </visual>
    <collision>
      <origin rpy="0 0 0" xyz="0 0 0"/>
      <geometry>
        <mesh filename="package://probot_description/meshes/link_5.STL"/>
      </geometry>
    </collision>
  </link>
  <joint name="joint_5" type="revolute">
    <origin rpy="0 0 0" xyz="0.20586 0 0"/>
    <parent link="link_4"/>
    <child link="link_5"/>
    <axis xyz="0 0 1"/>
    <limit effort="100" lower="-0.7854" upper="3.9270" velocity="3"/>
  </joint>
  <link name="link_6">
    <inertial>
      <origin rpy="0 0 0" xyz="-0.010934 0.23134 0.0051509"/>
      <mass value="0.00628105868776632"/>
      <inertia ixx="5.52992389755476E-07" ixy="-2.81554428275222E-22" ixz="-1.40088624914581E-22" iyy="5.52992389755476E-07" iyz="4.83070888700992E-24" izz="1.08002978042972E-06"/>
    </inertial>
    <visual>
      <origin rpy="0 0 0" xyz="0 0 0"/>
      <geometry>
        <mesh filename="package://probot_description/meshes/link_6.STL"/>
      </geometry>
      <material name="robot_color">
        <color rgba="0.79216 0.81961 0.93333 1"/>
      </material>
    </visual>
    <collision>
      <origin rpy="0 0 0" xyz="0 0 0"/>
      <geometry>
        <mesh filename="package://probot_description/meshes/link_6.STL"/>
      </geometry>
    </collision>
  </link>
  <joint name="joint_6" type="revolute">
    <origin rpy="0 0 0" xyz="0 -0.042 0"/>
    <parent link="link_5"/>
    <child link="link_6"/>
    <axis xyz="0 -1 0"/>
    <limit effort="100" lower="-3.1416" upper="3.1416" velocity="3"/>
  </joint>
  <link name="tool0"/>
  <joint name="joint_tool0" type="fixed">
    <origin rpy="0 0 0" xyz="0 -0.013 0"/>
    <parent link="link_6"/>
    <child link="tool0"/>
  </joint>
  <transmission name="tran1">
    <type>transmission_interface/SimpleTransmission</type>
    <joint name="joint_1">
      <hardwareInterface>hardware_interface/PositionJointInterface</hardwareInterface>
    </joint>
    <actuator name="motor1">
      <hardwareInterface>hardware_interface/PositionJointInterface</hardwareInterface>
      <mechanicalReduction>1</mechanicalReduction>
    </actuator>
  </transmission>
  <transmission name="tran1">
    <type>transmission_interface/SimpleTransmission</type>
    <joint name="joint_2">
      <hardwareInterface>hardware_interface/PositionJointInterface</hardwareInterface>
    </joint>
    <actuator name="motor1">
      <hardwareInterface>hardware_interface/PositionJointInterface</hardwareInterface>
      <mechanicalReduction>1</mechanicalReduction>
    </actuator>
  </transmission>
  <transmission name="tran1">
    <type>transmission_interface/SimpleTransmission</type>
    <joint name="joint_3">
      <hardwareInterface>hardware_interface/PositionJointInterface</hardwareInterface>
    </joint>
    <actuator name="motor1">
      <hardwareInterface>hardware_interface/PositionJointInterface</hardwareInterface>
      <mechanicalReduction>1</mechanicalReduction>
    </actuator>
  </transmission>
  <transmission name="tran1">
    <type>transmission_interface/SimpleTransmission</type>
    <joint name="joint_4">
      <hardwareInterface>hardware_interface/PositionJointInterface</hardwareInterface>
    </joint>
    <actuator name="motor1">
      <hardwareInterface>hardware_interface/PositionJointInterface</hardwareInterface>
      <mechanicalReduction>1</mechanicalReduction>
    </actuator>
  </transmission>
  <transmission name="tran1">
    <type>transmission_interface/SimpleTransmission</type>
    <joint name="joint_5">
      <hardwareInterface>hardware_interface/PositionJointInterface</hardwareInterface>
    </joint>
    <actuator name="motor1">
      <hardwareInterface>hardware_interface/PositionJointInterface</hardwareInterface>
      <mechanicalReduction>1</mechanicalReduction>
    </actuator>
  </transmission>
  <transmission name="tran1">
    <type>transmission_interface/SimpleTransmission</type>
    <joint name="joint_6">
      <hardwareInterface>hardware_interface/PositionJointInterface</hardwareInterface>
    </joint>
    <actuator name="motor1">
      <hardwareInterface>hardware_interface/PositionJointInterface</hardwareInterface>
      <mechanicalReduction>1</mechanicalReduction>
    </actuator>
  </transmission>
  <!-- ros_control plugin -->
  <gazebo>
    <plugin filename="libgazebo_ros_control.so" name="gazebo_ros_control">
      <robotNamespace>/probot_anno</robotNamespace>
      <robotSimType>gazebo_ros_control/DefaultRobotHWSim</robotSimType>
      <legacyModeNS>true</legacyModeNS>
    </plugin>
  </gazebo>
  <joint name="gripper_base_joint" type="fixed">
    <parent link="tool0"/>
    <child link="gripper_base"/>
    <origin rpy="1.507 0 0" xyz="0 0 0"/>
  </joint>
  <link name="gripper_base">
    <inertial>
      <origin rpy="0 0 0" xyz="0.0033936 0.0039094 0.136475"/>
      <mass value="0.014348"/>
      <inertia ixx="5.843E-06" ixy="-2.908E-07" ixz="-6.459E-08" iyy="6.430E-06" iyz="-1.969E-07" izz="3.109E-06"/>
    </inertial>
    <visual>
      <origin rpy="0 0 0" xyz="0 0 0"/>
      <geometry>
        <mesh filename="package://probot_description/meshes/gripper_base.STL"/>
      </geometry>
      <material name="grey">
        <color rgba="0.639 0.666 0.678 1"/>
      </material>
    </visual>
    <collision>
      <origin rpy="0 0 0" xyz="0 0 0"/>
      <geometry>
        <mesh filename="package://probot_description/meshes/gripper_base.STL"/>
      </geometry>
    </collision>
  </link>
  <link name="finger1">
    <inertial>
      <origin rpy="0 0 0" xyz="-0.002035 0.019077 0.000525"/>
      <mass value="0.007828"/>
      <inertia ixx="3.772E-06" ixy="8.020E-07" ixz="3.767E-10" iyy="1.086E-06" iyz="-3.563E-09" izz="4.725E-06"/>
    </inertial>
    <visual>
      <origin rpy="0 0 0" xyz="0 0 0"/>
      <geometry>
        <mesh filename="package://probot_description/meshes/finger1.STL"/>
      </geometry>
      <material name="silver">
        <color rgba="0.792 0.819 0.933 1"/>
      </material>
    </visual>
    <collision>
      <origin rpy="0 0 0" xyz="0 0 0"/>
      <geometry>
        <mesh filename="package://probot_description/meshes/finger1.STL"/>
      </geometry>
    </collision>
  </link>
  <joint name="finger_joint1" type="revolute">
    <origin rpy="1.5708 0 1.5708" xyz="-0.000050192 0.048 0.10015"/>
    <parent link="gripper_base"/>
    <child link="finger1"/>
    <axis xyz="0 0 1"/>
    <limit effort="0.1" lower="-1.57" upper="1.57" velocity="0.1"/>
  </joint>
  <link name="finger2">
    <inertial>
      <origin rpy="0 0 0" xyz="-0.003855 0.018793 -0.002724"/>
      <mass value="0.007828"/>
      <inertia ixx="3.594E-06" ixy="1.043E-06" ixz="7.168E-10" iyy="1.264E-06" iyz="-3.510E-09" izz="4.725E-06"/>
    </inertial>
    <visual>
      <origin rpy="0 0 0" xyz="0 0 0"/>
      <geometry>
        <mesh filename="package://probot_description/meshes/finger2.STL"/>
      </geometry>
    </visual>
    <collision>
      <origin rpy="0 0 0" xyz="0 0 0"/>
      <geometry>
        <mesh filename="package://probot_description/meshes/finger2.STL"/>
      </geometry>
    </collision>
  </link>
  <joint name="finger_joint2" type="revolute">
    <origin rpy="1.5708 0 -0.5236" xyz="0.040469 -0.025905 0.10015"/>
    <parent link="gripper_base"/>
    <child link="finger2"/>
    <axis xyz="0 0 1"/>
    <limit effort="0.1" lower="-1.57" upper="1.57" velocity="0.1"/>
    <mimic joint="finger_joint1" multiplier="1.0" offset="0.0"/>
  </joint>
  <link name="finger3">
    <inertial>
      <origin rpy="0 0 0" xyz="-0.001815 0.019099 -0.002724"/>
      <mass value="0.007828"/>
      <inertia ixx="3.790E-06" ixy="7.709E-07" ixz="3.357E-10" iyy="1.068E-06" iyz="-3.567E-09" izz="4.725E-06"/>
    </inertial>
    <visual>
      <origin rpy="0 0 0" xyz="0 0 0"/>
      <geometry>
        <mesh filename="package://probot_description/meshes/finger3.STL"/>
      </geometry>
    </visual>
    <collision>
      <origin rpy="0 0 0" xyz="0 0 0"/>
      <geometry>
        <mesh filename="package://probot_description/meshes/finger3.STL"/>
      </geometry>
    </collision>
  </link>
  <joint name="finger_joint3" type="revolute">
    <origin rpy="1.5708 0 -2.618" xyz="-0.042669 -0.022095 0.10015"/>
    <parent link="gripper_base"/>
    <child link="finger3"/>
    <axis xyz="0 0 1"/>
    <limit effort="0.1" lower="-1.57" upper="1.57" velocity="0.1"/>
    <mimic joint="finger_joint1" multiplier="1.0" offset="0.0"/>
  </joint>
</robot>
